Workbook

Sheet Summary
A1: Wheel Alignment Shop – New Brunswick: Financial Summary
A2: Change assumptions on the Inputs sheet. Estimates only — verify with local quotes before committing money.
A4: Scenario
A5: City | B5: =Inputs!B4
A6: Setup level | B6: =Inputs!B5
A7: Total startup cost | B7: =Inputs!B43
A8: Loan amount | B8: =Inputs!B44
A9: Owner equity required | B9: =Inputs!B46
A10: Monthly loan payment | B10: =Inputs!B45
A12: 3-year projection
A13: Metric | B13: Year 1 | C13: Year 2 | D13: Year 3
A14: Alignments | B14: =SUMIFS('Monthly P&L'!$G$5:$G$40,'Monthly P&L'!$B$5:$B$40,1) | C14: =SUMIFS('Monthly P&L'!$G$5:$G$40,'Monthly P&L'!$B$5:$B$40,2) | D14: =SUMIFS('Monthly P&L'!$G$5:$G$40,'Monthly P&L'!$B$5:$B$40,3)
A15: Alignment revenue | B15: =SUMIFS('Monthly P&L'!$H$5:$H$40,'Monthly P&L'!$B$5:$B$40,1) | C15: =SUMIFS('Monthly P&L'!$H$5:$H$40,'Monthly P&L'!$B$5:$B$40,2) | D15: =SUMIFS('Monthly P&L'!$H$5:$H$40,'Monthly P&L'!$B$5:$B$40,3)
A16: Balancing revenue | B16: =SUMIFS('Monthly P&L'!$I$5:$I$40,'Monthly P&L'!$B$5:$B$40,1) | C16: =SUMIFS('Monthly P&L'!$I$5:$I$40,'Monthly P&L'!$B$5:$B$40,2) | D16: =SUMIFS('Monthly P&L'!$I$5:$I$40,'Monthly P&L'!$B$5:$B$40,3)
A17: Tire swap revenue | B17: =SUMIFS('Monthly P&L'!$J$5:$J$40,'Monthly P&L'!$B$5:$B$40,1) | C17: =SUMIFS('Monthly P&L'!$J$5:$J$40,'Monthly P&L'!$B$5:$B$40,2) | D17: =SUMIFS('Monthly P&L'!$J$5:$J$40,'Monthly P&L'!$B$5:$B$40,3)
A18: Storage revenue | B18: =SUMIFS('Monthly P&L'!$K$5:$K$40,'Monthly P&L'!$B$5:$B$40,1) | C18: =SUMIFS('Monthly P&L'!$K$5:$K$40,'Monthly P&L'!$B$5:$B$40,2) | D18: =SUMIFS('Monthly P&L'!$K$5:$K$40,'Monthly P&L'!$B$5:$B$40,3)
A19: Parts & tire gross profit | B19: =SUMIFS('Monthly P&L'!$L$5:$L$40,'Monthly P&L'!$B$5:$B$40,1) | C19: =SUMIFS('Monthly P&L'!$L$5:$L$40,'Monthly P&L'!$B$5:$B$40,2) | D19: =SUMIFS('Monthly P&L'!$L$5:$L$40,'Monthly P&L'!$B$5:$B$40,3)
A20: Total revenue & gross profit | B20: =SUMIFS('Monthly P&L'!$M$5:$M$40,'Monthly P&L'!$B$5:$B$40,1) | C20: =SUMIFS('Monthly P&L'!$M$5:$M$40,'Monthly P&L'!$B$5:$B$40,2) | D20: =SUMIFS('Monthly P&L'!$M$5:$M$40,'Monthly P&L'!$B$5:$B$40,3)
A21: Total costs | B21: =SUMIFS('Monthly P&L'!$U$5:$U$40,'Monthly P&L'!$B$5:$B$40,1) | C21: =SUMIFS('Monthly P&L'!$U$5:$U$40,'Monthly P&L'!$B$5:$B$40,2) | D21: =SUMIFS('Monthly P&L'!$U$5:$U$40,'Monthly P&L'!$B$5:$B$40,3)
A22: Net profit (pre-tax) | B22: =SUMIFS('Monthly P&L'!$V$5:$V$40,'Monthly P&L'!$B$5:$B$40,1) | C22: =SUMIFS('Monthly P&L'!$V$5:$V$40,'Monthly P&L'!$B$5:$B$40,2) | D22: =SUMIFS('Monthly P&L'!$V$5:$V$40,'Monthly P&L'!$B$5:$B$40,3)
A23: Net margin | B23: =IF(B20=0,0,B22/B20) | C23: =IF(C20=0,0,C22/C20) | D23: =IF(D20=0,0,D22/D20)
A24: Average net profit per month | B24: =B22/12 | C24: =C22/12 | D24: =D22/12
A26: Breakeven & payback (mature operations, selected city)
A27: Contribution per alignment (incl. balancing attach) | B27: =(Inputs!$E$12+Inputs!B22*Inputs!B23)*(1-Inputs!B29-Inputs!B30)
A28: Other monthly gross profit (tires, storage, parts) | B28: =(Inputs!B24*Inputs!B25+Inputs!B26*Inputs!B27*2)*(1-Inputs!B30)/12+Inputs!B28
A29: Fixed monthly costs (rent, wages, overhead, loan, owner draw) | B29: =Inputs!B17*Inputs!$E$10/12+Inputs!B18*Inputs!B19*Inputs!$E$11*(1+Inputs!B20)+SUM(Inputs!B31:B36)+Inputs!B45+Inputs!B37
A30: Breakeven alignments per working day | B30: =IF(B27=0,0,MAX(0,(B29-B28)/(B27*Inputs!B21)))
A31: Month cumulative profit repays owner equity | B31: =IF(COUNT('Monthly P&L'!X5:X40)=0,"Beyond 36 months",MIN('Monthly P&L'!X5:X40))
A32: Breakeven alignments/day with NO tire, storage or parts income | B32: =IF(B27=0,0,B29/(B27*Inputs!B21))
A34: City comparison – mature-year net profit (same shop, city presets)
A35: City | B35: Mature net profit / yr | C35: Breakeven alignments/day | D35: Rent / month
A36: Moncton | B36: =12*(Inputs!B13*Inputs!$B$21*((Inputs!B12+Inputs!$B$22*Inputs!$B$23)*(1-Inputs!$B$29-Inputs!$B$30))+$B$28-(Inputs!$B$17*Inputs!B10/12+Inputs!$B$18*Inputs!$B$19*Inputs!B11*(1+Inputs!$B$20)+SUM(Inputs!$B$31:$B$36)+Inputs!$B$45+Inputs!$B$37)) | C36: =MAX(0,((Inputs!$B$17*Inputs!B10/12+Inputs!$B$18*Inputs!$B$19*Inputs!B11*(1+Inputs!$B$20)+SUM(Inputs!$B$31:$B$36)+Inputs!$B$45+Inputs!$B$37)-$B$28)/(((Inputs!B12+Inputs!$B$22*Inputs!$B$23)*(1-Inputs!$B$29-Inputs!$B$30))*Inputs!$B$21)) | D36: =Inputs!$B$17*Inputs!B10/12
A37: Saint John | B37: =12*(Inputs!C13*Inputs!$B$21*((Inputs!C12+Inputs!$B$22*Inputs!$B$23)*(1-Inputs!$B$29-Inputs!$B$30))+$B$28-(Inputs!$B$17*Inputs!C10/12+Inputs!$B$18*Inputs!$B$19*Inputs!C11*(1+Inputs!$B$20)+SUM(Inputs!$B$31:$B$36)+Inputs!$B$45+Inputs!$B$37)) | C37: =MAX(0,((Inputs!$B$17*Inputs!C10/12+Inputs!$B$18*Inputs!$B$19*Inputs!C11*(1+Inputs!$B$20)+SUM(Inputs!$B$31:$B$36)+Inputs!$B$45+Inputs!$B$37)-$B$28)/(((Inputs!C12+Inputs!$B$22*Inputs!$B$23)*(1-Inputs!$B$29-Inputs!$B$30))*Inputs!$B$21)) | D37: =Inputs!$B$17*Inputs!C10/12
A38: Fredericton | B38: =12*(Inputs!D13*Inputs!$B$21*((Inputs!D12+Inputs!$B$22*Inputs!$B$23)*(1-Inputs!$B$29-Inputs!$B$30))+$B$28-(Inputs!$B$17*Inputs!D10/12+Inputs!$B$18*Inputs!$B$19*Inputs!D11*(1+Inputs!$B$20)+SUM(Inputs!$B$31:$B$36)+Inputs!$B$45+Inputs!$B$37)) | C38: =MAX(0,((Inputs!$B$17*Inputs!D10/12+Inputs!$B$18*Inputs!$B$19*Inputs!D11*(1+Inputs!$B$20)+SUM(Inputs!$B$31:$B$36)+Inputs!$B$45+Inputs!$B$37)-$B$28)/(((Inputs!D12+Inputs!$B$22*Inputs!$B$23)*(1-Inputs!$B$29-Inputs!$B$30))*Inputs!$B$21)) | D38: =Inputs!$B$17*Inputs!D10/12
A40: Pre-tax figures, before owner salary unless Inputs!B37 is set. Revenue excludes 15% HST.

Sheet Inputs
A1: NB Wheel Alignment Shop – Inputs & Assumptions
A2: Edit BLUE cells (YELLOW = key choices). Black cells are formulas. All figures CAD, excl. HST.
A4: Selected city | B4: Moncton | C4: Pick from dropdown: Moncton, Saint John, Fredericton
A5: Shop setup level (Lean / Pro) | B5: Lean | C5: Lean = budget/used equipment; Pro = premium 3D aligner + ADAS kit
A6: Opening month (1=Jan … 12=Dec) | B6: 4 | C6: Example: 4 = open in April, just before spring pothole season
A8: City presets
A9: Item | B9: Moncton | C9: Saint John | D9: Fredericton | E9: Active (selected city) | F9: Notes / source
A10: Gross rent ($/sq ft/yr, net + additional rent) | B10: 24 | C10: 20 | D10: 22 | E10: =INDEX(B10:D10,MATCH($B$4,$B$9:$D$9,0)) | F10: Estimate. Moncton industrial units listed ~$13–18 net + ~$6–11 additional (Realtor.ca/CBRE 2026)
A11: Technician wage ($/hr) | B11: 28 | C11: 27 | D11: 28 | E11: =INDEX(B11:D11,MATCH($B$4,$B$9:$D$9,0)) | F11: NB avg ~$20/hr (range $17–27, Payscale/Job Bank); experienced alignment/Red Seal tech assumed higher
A12: Avg 4-wheel alignment price ($) | B12: 135 | C12: 130 | D12: 135 | E12: =INDEX(B12:D12,MATCH($B$4,$B$9:$D$9,0)) | F12: Estimate from typical NB range $110–170
A13: Alignments/day at maturity | B13: 9 | C13: 8 | D13: 8 | E13: =INDEX(B13:D13,MATCH($B$4,$B$9:$D$9,0)) | F13: Assumption – established 2-bay shop
A14: Metro population (approx., info only) | B14: 180000 | C14: 135000 | D14: 115000 | E14: =INDEX(B14:D14,MATCH($B$4,$B$9:$D$9,0)) | F14: Approximate CMA populations
A16: Operating assumptions
A17: Shop size (sq ft) | B17: 2200 | C17: 2 bays + office/waiting + tire storage
A18: Number of technicians | B18: 2 | C18: Owner may replace one tech
A19: Paid hours per tech per month | B19: 173 | C19: 40 hrs × 52 wks / 12
A20: Payroll burden (CPP, EI, WorkSafeNB, vacation) | B20: 0.15 | C20: Estimate
A21: Working days per month | B21: 22
A22: Balancing attach rate (% of alignments) | B22: 0.4 | C22: Share of alignment customers also buying balancing
A23: Balancing price, 4 wheels ($) | B23: 80 | C23: NB range ~$60–100
A24: Seasonal tire swaps per year at maturity | B24: 900 | C24: Spring + fall changeovers
A25: Tire swap price ($) | B25: 70 | C25: On-rim swap ~$50–90
A26: Tire storage customers at maturity | B26: 250
A27: Storage price per season ($) | B27: 80 | C27: Billed spring and fall
A28: Parts & tire sales gross profit / month at maturity ($) | B28: 4000 | C28: Suspension parts + tire sales, gross profit only
A29: Consumables (% of alignment + balancing revenue) | B29: 0.04 | C29: Weights, valve stems, shims
A30: Card / payment fees (% of service revenue) | B30: 0.02
A31: Utilities incl. winter heat ($/month) | B31: 1300
A32: Garage liability insurance ($/month) | B32: 650
A33: Software, phone, internet ($/month) | B33: 400 | C33: Shop management + alignment database
A34: Marketing ($/month) | B34: 700 | C34: Google ads, reviews, signage
A35: Accounting & legal ($/month) | B35: 300
A36: Misc., repairs, equipment calibration ($/month) | B36: 400
A37: Owner draw ($/month) | B37: 0 | C37: Set >0 to pay yourself before profit
A39: Financing
A40: Share of startup cost financed | B40: 0.7 | C40: CSBFP / BDC / equipment lease
A41: Interest rate (annual) | B41: 0.085
A42: Loan term (years) | B42: 7
A43: Total startup cost | B43: ='Startup Costs'!D14
A44: Loan amount | B44: =B43*B40
...

Sheet Startup Costs
A1: Startup Costs (CAD)
A2: Edit the BLUE Lean/Pro estimates; column D follows the setup level chosen on Inputs!B5.
A4: Item | B4: Lean ($) | C4: Pro ($) | D4: Selected ($) | E4: Notes
A5: Wheel alignment machine | B5: 15000 | C5: 47500 | D5: =IF(Inputs!$B$5="Pro",C5,B5) | E5: Lean: budget 3D/CCD; Pro: Hunter / John Bean 3D
A6: Alignment lift (4-post or scissor) | B6: 12500 | C6: 24000 | D6: =IF(Inputs!$B$5="Pro",C6,B6)
A7: Wheel balancer | B7: 5000 | C7: 11500 | D7: =IF(Inputs!$B$5="Pro",C7,B7) | E7: Pro: road-force balancer
A8: Tire changer | B8: 5000 | C8: 11500 | D8: =IF(Inputs!$B$5="Pro",C8,B8)
A9: Compressor, air lines, tools, impact guns | B9: 6500 | C9: 15000 | D9: =IF(Inputs!$B$5="Pro",C9,B9)
A10: ADAS calibration kit | B10: 0 | C10: 30000 | D10: =IF(Inputs!$B$5="Pro",C10,B10) | E10: Optional; high-value add-on for newer vehicles
A11: Leasehold improvements, signage, computer & software | B11: 14000 | C11: 42500 | D11: =IF(Inputs!$B$5="Pro",C11,B11)
A12: Rent deposit, insurance, permits, launch marketing | B12: 7500 | C12: 15000 | D12: =IF(Inputs!$B$5="Pro",C12,B12)
A13: Working capital (≈3 months) | B13: 20000 | C13: 45000 | D13: =IF(Inputs!$B$5="Pro",C13,B13) | E13: Cash buffer during ramp-up
A14: Total startup cost | B14: =SUM(B5:B13) | C14: =SUM(C5:C13) | D14: =SUM(D5:D13)
A16: Buying used equipment or taking over an existing garage can cut costs 30–50%.

Sheet Monthly P&L
A1: 36-Month Projection (CAD)
A2: All formulas — driven by Inputs. Parts & tire sales are shown as gross profit.
A4: Month # | B4: Year of operation | C4: Cal. month # | D4: Month | E4: Ramp % | F4: Season index | G4: Alignments | H4: Alignment revenue | I4: Balancing revenue | J4: Tire swap revenue | K4: Storage revenue | L4: Parts & tire GP | M4: Total revenue & GP | N4: Consumables | O4: Card fees | P4: Rent | Q4: Wages | R4: Other fixed | S4: Loan payment | T4: Owner draw | U4: Total costs | V4: Net profit (pre-tax) | W4: Cumulative net | X4: Payback flag
A5: 1 | B5: =INT((A5-1)/12)+1 | C5: =MOD(Inputs!$B$6-1+A5-1,12)+1 | D5: =INDEX(Inputs!$A$55:$A$66,C5) | E5: =IF(B5=1,Inputs!$B$49+(Inputs!$B$50-Inputs!$B$49)*(A5-1)/12,INDEX(Inputs!$B$49:$B$51,B5)) | F5: =INDEX(Inputs!$B$55:$B$66,C5) | G5: =Inputs!$E$13*Inputs!$B$21*E5*F5 | H5: =G5*Inputs!$E$12 | I5: =G5*Inputs!$B$22*Inputs!$B$23 | J5: =Inputs!$B$24*E5*INDEX(Inputs!$C$55:$C$66,C5)*Inputs!$B$25 | K5: =Inputs!$B$26*E5*INDEX(Inputs!$D$55:$D$66,C5)*Inputs!$B$27*2 | L5: =Inputs!$B$28*E5*F5 | M5: =SUM(H5:L5) | N5: =(H5+I5)*Inputs!$B$29 | O5: =SUM(H5:K5)*Inputs!$B$30 | P5: =Inputs!$B$17*Inputs!$E$10/12 | Q5: =Inputs!$B$18*Inputs!$B$19*Inputs!$E$11*(1+Inputs!$B$20) | R5: =SUM(Inputs!$B$31:$B$36) | S5: =Inputs!$B$45 | T5: =Inputs!$B$37 | U5: =SUM(N5:T5) | V5: =M5-U5 | W5: =V5 | X5: =IF(W5>=Inputs!$B$46,A5,"")
A6: 2 | B6: =INT((A6-1)/12)+1 | C6: =MOD(Inputs!$B$6-1+A6-1,12)+1 | D6: =INDEX(Inputs!$A$55:$A$66,C6) | E6: =IF(B6=1,Inputs!$B$49+(Inputs!$B$50-Inputs!$B$49)*(A6-1)/12,INDEX(Inputs!$B$49:$B$51,B6)) | F6: =INDEX(Inputs!$B$55:$B$66,C6) | G6: =Inputs!$E$13*Inputs!$B$21*E6*F6 | H6: =G6*Inputs!$E$12 | I6: =G6*Inputs!$B$22*Inputs!$B$23 | J6: =Inputs!$B$24*E6*INDEX(Inputs!$C$55:$C$66,C6)*Inputs!$B$25 | K6: =Inputs!$B$26*E6*INDEX(Inputs!$D$55:$D$66,C6)*Inputs!$B$27*2 | L6: =Inputs!$B$28*E6*F6 | M6: =SUM(H6:L6) | N6: =(H6+I6)*Inputs!$B$29 | O6: =SUM(H6:K6)*Inputs!$B$30 | P6: =Inputs!$B$17*Inputs!$E$10/12 | Q6: =Inputs!$B$18*Inputs!$B$19*Inputs!$E$11*(1+Inputs!$B$20) | R6: =SUM(Inputs!$B$31:$B$36) | S6: =Inputs!$B$45 | T6: =Inputs!$B$37 | U6: =SUM(N6:T6) | V6: =M6-U6 | W6: =W5+V6 | X6: =IF(W6>=Inputs!$B$46,A6,"")
A7: 3 | B7: =INT((A7-1)/12)+1 | C7: =MOD(Inputs!$B$6-1+A7-1,12)+1 | D7: =INDEX(Inputs!$A$55:$A$66,C7) | E7: =IF(B7=1,Inputs!$B$49+(Inputs!$B$50-Inputs!$B$49)*(A7-1)/12,INDEX(Inputs!$B$49:$B$51,B7)) | F7: =INDEX(Inputs!$B$55:$B$66,C7) | G7: =Inputs!$E$13*Inputs!$B$21*E7*F7 | H7: =G7*Inputs!$E$12 | I7: =G7*Inputs!$B$22*Inputs!$B$23 | J7: =Inputs!$B$24*E7*INDEX(Inputs!$C$55:$C$66,C7)*Inputs!$B$25 | K7: =Inputs!$B$26*E7*INDEX(Inputs!$D$55:$D$66,C7)*Inputs!$B$27*2 | L7: =Inputs!$B$28*E7*F7 | M7: =SUM(H7:L7) | N7: =(H7+I7)*Inputs!$B$29 | O7: =SUM(H7:K7)*Inputs!$B$30 | P7: =Inputs!$B$17*Inputs!$E$10/12 | Q7: =Inputs!$B$18*Inputs!$B$19*Inputs!$E$11*(1+Inputs!$B$20) | R7: =SUM(Inputs!$B$31:$B$36) | S7: =Inputs!$B$45 | T7: =Inputs!$B$37 | U7: =SUM(N7:T7) | V7: =M7-U7 | W7: =W6+V7 | X7: =IF(W7>=Inputs!$B$46,A7,"")
A8: 4 | B8: =INT((A8-1)/12)+1 | C8: =MOD(Inputs!$B$6-1+A8-1,12)+1 | D8: =INDEX(Inputs!$A$55:$A$66,C8) | E8: =IF(B8=1,Inputs!$B$49+(Inputs!$B$50-Inputs!$B$49)*(A8-1)/12,INDEX(Inputs!$B$49:$B$51,B8)) | F8: =INDEX(Inputs!$B$55:$B$66,C8) | G8: =Inputs!$E$13*Inputs!$B$21*E8*F8 | H8: =G8*Inputs!$E$12 | I8: =G8*Inputs!$B$22*Inputs!$B$23 | J8: =Inputs!$B$24*E8*INDEX(Inputs!$C$55:$C$66,C8)*Inputs!$B$25 | K8: =Inputs!$B$26*E8*INDEX(Inputs!$D$55:$D$66,C8)*Inputs!$B$27*2 | L8: =Inputs!$B$28*E8*F8 | M8: =SUM(H8:L8) | N8: =(H8+I8)*Inputs!$B$29 | O8: =SUM(H8:K8)*Inputs!$B$30 | P8: =Inputs!$B$17*Inputs!$E$10/12 | Q8: =Inputs!$B$18*Inputs!$B$19*Inputs!$E$11*(1+Inputs!$B$20) | R8: =SUM(Inputs!$B$31:$B$36) | S8: =Inputs!$B$45 | T8: =Inputs!$B$37 | U8: =SUM(N8:T8) | V8: =M8-U8 | W8: =W7+V8 | X8: =IF(W8>=Inputs!$B$46,A8,"")
A9: 5 | B9: =INT((A9-1)/12)+1 | C9: =MOD(Inputs!$B$6-1+A9-1,12)+1 | D9: =INDEX(Inputs!$A$55:$A$66,C9) | E9: =IF(B9=1,Inputs!$B$49+(Inputs!$B$50-Inputs!$B$49)*(A9-1)/12,INDEX(Inputs!$B$49:$B$51,B9)) | F9: =INDEX(Inputs!$B$55:$B$66,C9) | G9: =Inputs!$E$13*Inputs!$B$21*E9*F9 | H9: =G9*Inputs!$E$12 | I9: =G9*Inputs!$B$22*Inputs!$B$23 | J9: =Inputs!$B$24*E9*INDEX(Inputs!$C$55:$C$66,C9)*Inputs!$B$25 | K9: =Inputs!$B$26*E9*INDEX(Inputs!$D$55:$D$66,C9)*Inputs!$B$27*2 | L9: =Inputs!$B$28*E9*F9 | M9: =SUM(H9:L9) | N9: =(H9+I9)*Inputs!$B$29 | O9: =SUM(H9:K9)*Inputs!$B$30 | P9: =Inputs!$B$17*Inputs!$E$10/12 | Q9: =Inputs!$B$18*Inputs!$B$19*Inputs!$E$11*(1+Inputs!$B$20) | R9: =SUM(Inputs!$B$31:$B$36) | S9: =Inputs!$B$45 | T9: =Inputs!$B$37 | U9: =SUM(N9:T9) | V9: =M9-U9 | W9: =W8+V9 | X9: =IF(W9>=Inputs!$B$46,A9,"")
A10: 6 | B10: =INT((A10-1)/12)+1 | C10: =MOD(Inputs!$B$6-1+A10-1,12)+1 | D10: =INDEX(Inputs!$A$55:$A$66,C10) | E10: =IF(B10=1,Inputs!$B$49+(Inputs!$B$50-Inputs!$B$49)*(A10-1)/12,INDEX(Inputs!$B$49:$B$51,B10)) | F10: =INDEX(Inputs!$B$55:$B$66,C10) | G10: =Inputs!$E$13*Inputs!$B$21*E10*F10 | H10: =G10*Inputs!$E$12 | I10: =G10*Inputs!$B$22*Inputs!$B$23 | J10: =Inputs!$B$24*E10*INDEX(Inputs!$C$55:$C$66,C10)*Inputs!$B$25 | K10: =Inputs!$B$26*E10*INDEX(Inputs!$D$55:$D$66,C10)*Inputs!$B$27*2 | L10: =Inputs!$B$28*E10*F10 | M10: =SUM(H10:L10) | N10: =(H10+I10)*Inputs!$B$29 | O10: =SUM(H10:K10)*Inputs!$B$30 | P10: =Inputs!$B$17*Inputs!$E$10/12 | Q10: =Inputs!$B$18*Inputs!$B$19*Inputs!$E$11*(1+Inputs!$B$20) | R10: =SUM(Inputs!$B$31:$B$36) | S10: =Inputs!$B$45 | T10: =Inputs!$B$37 | U10: =SUM(N10:T10) | V10: =M10-U10 | W10: =W9+V10 | X10: =IF(W10>=Inputs!$B$46,A10,"")
A11: 7 | B11: =INT((A11-1)/12)+1 | C11: =MOD(Inputs!$B$6-1+A11-1,12)+1 | D11: =INDEX(Inputs!$A$55:$A$66,C11) | E11: =IF(B11=1,Inputs!$B$49+(Inputs!$B$50-Inputs!$B$49)*(A11-1)/12,INDEX(Inputs!$B$49:$B$51,B11)) | F11: =INDEX(Inputs!$B$55:$B$66,C11) | G11: =Inputs!$E$13*Inputs!$B$21*E11*F11 | H11: =G11*Inputs!$E$12 | I11: =G11*Inputs!$B$22*Inputs!$B$23 | J11: =Inputs!$B$24*E11*INDEX(Inputs!$C$55:$C$66,C11)*Inputs!$B$25 | K11: =Inputs!$B$26*E11*INDEX(Inputs!$D$55:$D$66,C11)*Inputs!$B$27*2 | L11: =Inputs!$B$28*E11*F11 | M11: =SUM(H11:L11) | N11: =(H11+I11)*Inputs!$B$29 | O11: =SUM(H11:K11)*Inputs!$B$30 | P11: =Inputs!$B$17*Inputs!$E$10/12 | Q11: =Inputs!$B$18*Inputs!$B$19*Inputs!$E$11*(1+Inputs!$B$20) | R11: =SUM(Inputs!$B$31:$B$36) | S11: =Inputs!$B$45 | T11: =Inputs!$B$37 | U11: =SUM(N11:T11) | V11: =M11-U11 | W11: =W10+V11 | X11: =IF(W11>=Inputs!$B$46,A11,"")
A12: 8 | B12: =INT((A12-1)/12)+1 | C12: =MOD(Inputs!$B$6-1+A12-1,12)+1 | D12: =INDEX(Inputs!$A$55:$A$66,C12) | E12: =IF(B12=1,Inputs!$B$49+(Inputs!$B$50-Inputs!$B$49)*(A12-1)/12,INDEX(Inputs!$B$49:$B$51,B12)) | F12: =INDEX(Inputs!$B$55:$B$66,C12) | G12: =Inputs!$E$13*Inputs!$B$21*E12*F12 | H12: =G12*Inputs!$E$12 | I12: =G12*Inputs!$B$22*Inputs!$B$23 | J12: =Inputs!$B$24*E12*INDEX(Inputs!$C$55:$C$66,C12)*Inputs!$B$25 | K12: =Inputs!$B$26*E12*INDEX(Inputs!$D$55:$D$66,C12)*Inputs!$B$27*2 | L12: =Inputs!$B$28*E12*F12 | M12: =SUM(H12:L12) | N12: =(H12+I12)*Inputs!$B$29 | O12: =SUM(H12:K12)*Inputs!$B$30 | P12: =Inputs!$B$17*Inputs!$E$10/12 | Q12: =Inputs!$B$18*Inputs!$B$19*Inputs!$E$11*(1+Inputs!$B$20) | R12: =SUM(Inputs!$B$31:$B$36) | S12: =Inputs!$B$45 | T12: =Inputs!$B$37 | U12: =SUM(N12:T12) | V12: =M12-U12 | W12: =W11+V12 | X12: =IF(W12>=Inputs!$B$46,A12,"")
A13: 9 | B13: =INT((A13-1)/12)+1 | C13: =MOD(Inputs!$B$6-1+A13-1,12)+1 | D13: =INDEX(Inputs!$A$55:$A$66,C13) | E13: =IF(B13=1,Inputs!$B$49+(Inputs!$B$50-Inputs!$B$49)*(A13-1)/12,INDEX(Inputs!$B$49:$B$51,B13)) | F13: =INDEX(Inputs!$B$55:$B$66,C13) | G13: =Inputs!$E$13*Inputs!$B$21*E13*F13 | H13: =G13*Inputs!$E$12 | I13: =G13*Inputs!$B$22*Inputs!$B$23 | J13: =Inputs!$B$24*E13*INDEX(Inputs!$C$55:$C$66,C13)*Inputs!$B$25 | K13: =Inputs!$B$26*E13*INDEX(Inputs!$D$55:$D$66,C13)*Inputs!$B$27*2 | L13: =Inputs!$B$28*E13*F13 | M13: =SUM(H13:L13) | N13: =(H13+I13)*Inputs!$B$29 | O13: =SUM(H13:K13)*Inputs!$B$30 | P13: =Inputs!$B$17*Inputs!$E$10/12 | Q13: =Inputs!$B$18*Inputs!$B$19*Inputs!$E$11*(1+Inputs!$B$20) | R13: =SUM(Inputs!$B$31:$B$36) | S13: =Inputs!$B$45 | T13: =Inputs!$B$37 | U13: =SUM(N13:T13) | V13: =M13-U13 | W13: =W12+V13 | X13: =IF(W13>=Inputs!$B$46,A13,"")
A14: 10 | B14: =INT((A14-1)/12)+1 | C14: =MOD(Inputs!$B$6-1+A14-1,12)+1 | D14: =INDEX(Inputs!$A$55:$A$66,C14) | E14: =IF(B14=1,Inputs!$B$49+(Inputs!$B$50-Inputs!$B$49)*(A14-1)/12,INDEX(Inputs!$B$49:$B$51,B14)) | F14: =INDEX(Inputs!$B$55:$B$66,C14) | G14: =Inputs!$E$13*Inputs!$B$21*E14*F14 | H14: =G14*Inputs!$E$12 | I14: =G14*Inputs!$B$22*Inputs!$B$23 | J14: =Inputs!$B$24*E14*INDEX(Inputs!$C$55:$C$66,C14)*Inputs!$B$25 | K14: =Inputs!$B$26*E14*INDEX(Inputs!$D$55:$D$66,C14)*Inputs!$B$27*2 | L14: =Inputs!$B$28*E14*F14 | M14: =SUM(H14:L14) | N14: =(H14+I14)*Inputs!$B$29 | O14: =SUM(H14:K14)*Inputs!$B$30 | P14: =Inputs!$B$17*Inputs!$E$10/12 | Q14: =Inputs!$B$18*Inputs!$B$19*Inputs!$E$11*(1+Inputs!$B$20) | R14: =SUM(Inputs!$B$31:$B$36) | S14: =Inputs!$B$45 | T14: =Inputs!$B$37 | U14: =SUM(N14:T14) | V14: =M14-U14 | W14: =W13+V14 | X14: =IF(W14>=Inputs!$B$46,A14,"")
A15: 11 | B15: =INT((A15-1)/12)+1 | C15: =MOD(Inputs!$B$6-1+A15-1,12)+1 | D15: =INDEX(Inputs!$A$55:$A$66,C15) | E15: =IF(B15=1,Inputs!$B$49+(Inputs!$B$50-Inputs!$B$49)*(A15-1)/12,INDEX(Inputs!$B$49:$B$51,B15)) | F15: =INDEX(Inputs!$B$55:$B$66,C15) | G15: =Inputs!$E$13*Inputs!$B$21*E15*F15 | H15: =G15*Inputs!$E$12 | I15: =G15*Inputs!$B$22*Inputs!$B$23 | J15: =Inputs!$B$24*E15*INDEX(Inputs!$C$55:$C$66,C15)*Inputs!$B$25 | K15: =Inputs!$B$26*E15*INDEX(Inputs!$D$55:$D$66,C15)*Inputs!$B$27*2 | L15: =Inputs!$B$28*E15*F15 | M15: =SUM(H15:L15) | N15: =(H15+I15)*Inputs!$B$29 | O15: =SUM(H15:K15)*Inputs!$B$30 | P15: =Inputs!$B$17*Inputs!$E$10/12 | Q15: =Inputs!$B$18*Inputs!$B$19*Inputs!$E$11*(1+Inputs!$B$20) | R15: =SUM(Inputs!$B$31:$B$36) | S15: =Inputs!$B$45 | T15: =Inputs!$B$37 | U15: =SUM(N15:T15) | V15: =M15-U15 | W15: =W14+V15 | X15: =IF(W15>=Inputs!$B$46,A15,"")
A16: 12 | B16: =INT((A16-1)/12)+1 | C16: =MOD(Inputs!$B$6-1+A16-1,12)+1 | D16: =INDEX(Inputs!$A$55:$A$66,C16) | E16: =IF(B16=1,Inputs!$B$49+(Inputs!$B$50-Inputs!$B$49)*(A16-1)/12,INDEX(Inputs!$B$49:$B$51,B16)) | F16: =INDEX(Inputs!$B$55:$B$66,C16) | G16: =Inputs!$E$13*Inputs!$B$21*E16*F16 | H16: =G16*Inputs!$E$12 | I16: =G16*Inputs!$B$22*Inputs!$B$23 | J16: =Inputs!$B$24*E16*INDEX(Inputs!$C$55:$C$66,C16)*Inputs!$B$25 | K16: =Inputs!$B$26*E16*INDEX(Inputs!$D$55:$D$66,C16)*Inputs!$B$27*2 | L16: =Inputs!$B$28*E16*F16 | M16: =SUM(H16:L16) | N16: =(H16+I16)*Inputs!$B$29 | O16: =SUM(H16:K16)*Inputs!$B$30 | P16: =Inputs!$B$17*Inputs!$E$10/12 | Q16: =Inputs!$B$18*Inputs!$B$19*Inputs!$E$11*(1+Inputs!$B$20) | R16: =SUM(Inputs!$B$31:$B$36) | S16: =Inputs!$B$45 | T16: =Inputs!$B$37 | U16: =SUM(N16:T16) | V16: =M16-U16 | W16: =W15+V16 | X16: =IF(W16>=Inputs!$B$46,A16,"")
A17: 13 | B17: =INT((A17-1)/12)+1 | C17: =MOD(Inputs!$B$6-1+A17-1,12)+1 | D17: =INDEX(Inputs!$A$55:$A$66,C17) | E17: =IF(B17=1,Inputs!$B$49+(Inputs!$B$50-Inputs!$B$49)*(A17-1)/12,INDEX(Inputs!$B$49:$B$51,B17)) | F17: =INDEX(Inputs!$B$55:$B$66,C17) | G17: =Inputs!$E$13*Inputs!$B$21*E17*F17 | H17: =G17*Inputs!$E$12 | I17: =G17*Inputs!$B$22*Inputs!$B$23 | J17: =Inputs!$B$24*E17*INDEX(Inputs!$C$55:$C$66,C17)*Inputs!$B$25 | K17: =Inputs!$B$26*E17*INDEX(Inputs!$D$55:$D$66,C17)*Inputs!$B$27*2 | L17: =Inputs!$B$28*E17*F17 | M17: =SUM(H17:L17) | N17: =(H17+I17)*Inputs!$B$29 | O17: =SUM(H17:K17)*Inputs!$B$30 | P17: =Inputs!$B$17*Inputs!$E$10/12 | Q17: =Inputs!$B$18*Inputs!$B$19*Inputs!$E$11*(1+Inputs!$B$20) | R17: =SUM(Inputs!$B$31:$B$36) | S17: =Inputs!$B$45 | T17: =Inputs!$B$37 | U17: =SUM(N17:T17) | V17: =M17-U17 | W17: =W16+V17 | X17: =IF(W17>=Inputs!$B$46,A17,"")
... A40: 36 | B40: =INT((A40-1)/12)+1 | C40: =MOD(Inputs!$B$6-1+A40-1,12)+1 | D40: =INDEX(Inputs!$A$55:$A$66,C40) | E40: =IF(B40=1,Inputs!$B$49+(Inputs!$B$50-Inputs!$B$49)*(A40-1)/12,INDEX(Inputs!$B$49:$B$51,B40)) | F40: =INDEX(Inputs!$B$55:$B$66,C40) | G40: =Inputs!$E$13*Inputs!$B$21*E40*F40 | H40: =G40*Inputs!$E$12 | I40: =G40*Inputs!$B$22*Inputs!$B$23 | J40: =Inputs!$B$24*E40*INDEX(Inputs!$C$55:$C$66,C40)*Inputs!$B$25 | K40: =Inputs!$B$26*E40*INDEX(Inputs!$D$55:$D$66,C40)*Inputs!$B$27*2 | L40: =Inputs!$B$28*E40*F40 | M40: =SUM(H40:L40) | N40: =(H40+I40)*Inputs!$B$29 | O40: =SUM(H40:K40)*Inputs!$B$30 | P40: =Inputs!$B$17*Inputs!$E$10/12 | Q40: =Inputs!$B$18*Inputs!$B$19*Inputs!$E$11*(1+Inputs!$B$20) | R40: =SUM(Inputs!$B$31:$B$36) | S40: =Inputs!$B$45 | T40: =Inputs!$B$37 | U40: =SUM(N40:T40) | V40: =M40-U40 | W40: =W39+V40 | X40: =IF(W40>=Inputs!$B$46,A40,"")

Sheet Notes & Sources
A1: Notes, Pricing Guide & Sources
A4: Typical NB service price | B4: Range (CAD, excl. HST)
A5: Alignment check | B5: $30–60
A6: Front (2-wheel) alignment | B6: $80–120
A7: 4-wheel alignment | B7: $110–170
A8: Truck / lifted / luxury | B8: $150–250
A9: Lifetime alignment package | B9: $200–300
A10: ADAS recalibration | B10: $200–450
A11: Wheel balancing (4) | B11: $60–100
A12: Seasonal tire swap (on rims) | B12: $50–90
A13: Mount & balance (off rims) | B13: $100–160
A14: Tire storage / season | B14: $60–100
A17: Checklist: Service NB business registration · CRA GST/HST number · WorkSafeNB · municipal zoning/occupancy permit · Tire Stewardship NB · optional NB Motor Vehicle Inspection Station licence.
A18: Funding: Canada Small Business Financing Program (CSBFP), BDC, Futurpreneur (ages 18–39), Opportunities NB, ACOA, supplier lease-to-own.
A19: Prices, rents and equipment costs are estimates — get 3 local quotes for each before committing.
A20: Sources: Payscale NB auto technician wages (2026); Job Bank wage data NB; CBRE Moncton Q2 2026; Realtor.ca Moncton industrial listings; Sunbit alignment cost guide.
